<?xml version="1.0"?>
<robot name="simple_robot"> <!-- Robot adı taşıyan ana etiket-->
    <material name="blue">
        <color rgba="0 0 1 1"/> <!-- red, yeşil, mavi, opaklık-->
    </material>
    <material name="green">
        <color rgba="0 1 0 1"/> <!-- red, yeşil, mavi, opaklık-->
    </material>

    <material name="red">
        <color rgba="1 0 0 1"/> <!-- red, yeşil, mavi, opaklık-->
    </material>
    
    <!-- her modelde "base_link" olması gerekli isimlendirme-->
    <link  name="base_link"> <!--robotun katı bir kısmı yani ana gövdesi-->
        <visual> <!-- şekil boyut konum gibi görsel özellikler tanımlanır içinde-->
            <geometry> <!-- öğenin geometrik şeklinin içinde barındırır-->
                <!--RViz Ölçümler metre cinsindendir-->
                <box size="0.5 0.5 1" /> <!-- width length height-->
            </geometry>
            <origin xyz="0 0 0" rpy="0 0 0" /> <!--rpy = (roll, pitch, yaw) x y z eksenlerinin saat yönünde dönüş açıları -->
            <!--xyz= merkez noktasının uzaydaki konumu -->
            <material name="blue"/>
        </visual>
    </link>

    <link name="second_link">
        <visual>
            <geometry>
                <cylinder radius="0.2" length="0.3"/>
            </geometry>
            <origin xyz="0 0 0" rpy="0 0 0"/>
            <material name="green"/>
        </visual>   
    </link>

    <link name="third_link">
        <visual>
            <geometry>
                <sphere radius="0.1"/>
            </geometry>
            <origin xyz="0 0 0" rpy="0 0 0"/>
            <material name="red"/>
        </visual>
    </link>


    <!--Bağlantı tf-->
    <joint name="base_second_joint" type="continuous"> <!--ana linke göre alt link haraket eder--> 
        <parent link="base_link"/> <!-- ana link-->
        <child link="second_link"/> <!-- alt link-->
        <origin xyz="0 0 1" rpy="0 0 0"/> <!-- tf koyduğumuz alt linkin görsel olrak koyduğumuz konumunu burda verdiğimmiz konum ile değiştirir  -->
        <axis xyz="0 0 1"/> <!-- döndüğü eksen -->
        <limit effort="100" velocity="1" lower="-3.14" upper="3.14"/> <!-- efor, hız, alt üst limitler -->
    </joint>

    <joint name="second_third_joint" type="fixed"><!-- alt link ana linke sabitlenmiştir yani döndürrüldüğüde ikiside döner-->
        <parent link="second_link"/>
        <child link="third_link"/>
        <origin xyz="0 0.4 0.225" rpy="0 0 0"/>
    </joint>

</robot>