<?xml version="1.0"?>
<robot name="simple_robot"> 
    <!-- renk materyalleri-->
    <material name="blue">
        <color rgba="0 0 1 1"/> 
    </material>
    <material name="green">
        <color rgba="0 1 0 1"/> 
    </material>

    <material name="red">
        <color rgba="1 0 0 1"/> 
    </material>
    
    <!--base_footprint, robotun referans çerçevesi  olarak kullanılan özel bir linktir.-->
    <!--Robotun zemindeki izdüşüm noktası-->
    <!--harita konumlandırmada merkezi referans sağlar-->
    <link name="base_footprint" />

    <!--linkler robotun belirl bir parçasıdır-->
    <link name="base_link"> 
        <visual> 
            <geometry> 
                <box size="0.5 0.5 0.5" />
            </geometry>
            <origin xyz="0 0 0" rpy="0 0 0" /> 
            <material name="blue"/>
        </visual>
    </link>

    <link name="second_link">
        <visual>
            <geometry>
                <cylinder radius="0.2" length="0.3"/>
            </geometry>
            <origin xyz="0 0 0" rpy="0 0 0"/>
            <material name="green"/>
        </visual>   
    </link>

    <link name="third_link">
        <visual>
            <geometry>
                <sphere radius="0.1"/>
            </geometry>
            <origin xyz="0 0 0" rpy="0 0 0"/>
            <material name="red"/>
        </visual>
    </link>

    <!--linkler arasındaki bağlantılar eklemlerdir-->
    <!-- tüm linkler bir bağlantı yapması gereklidir-->
    <!-- bu eklem türü parent linkine sabitlenmiş olmasını sağlar-->
    <joint name="base_joint" type="fixed"> <!--eklem ismi ve eklem türü oluşmaktadır-->
        <parent link="base_footprint" />
        <child link="base_link"/>
        <origin xyz="0 0 0.1" rpy="0 0 0" />
        <axis xyz="0 0 1"/>
    </joint>

    <!--bu eklem türü: tek bir eksen doğrultusunda sınırsız dönüş sağlar-->
    <joint name="base_second_joint" type="continuous"> 
        <parent link="base_link"/> 
        <child link="second_link"/> <!--child link parent link'e göre hareket eder-->
        <origin xyz="0 0 1" rpy="0 0 0"/> 
        <axis xyz="0 0 1"/> <!--dönme ekseni-->
        <limit effort="100" velocity="1" lower="-3.14" upper="3.14"/> 
        <!-- 
            limit:
                effort: maksimum uygulanabilir tork
                velocity: maksimum dönüş hızı
                lower: radyan minimum pozisyon(-180)
                upper: radyan cinsinden max ozisyon (180)
        -->
    </joint>

    
    <joint name="second_third_joint" type="fixed">
        <parent link="second_link"/>
        <child link="third_link"/>
        <origin xyz="0 0.4 0.225" rpy="0 0 0"/>
    </joint>

</robot>